<robot name="onshape" xmlns:xacro="http://www.ros.org/wiki/xacro">
	<!-- This first link called "world" is empty -->
    <link name="world"></link>
    
    <link name="wheel">
		<visual>
			<origin xyz="-1.41488e-17 -1.56125e-17 0.2032" rpy="0 -0.0149119 0" />
			<geometry>
				<mesh filename="file:///home/seanghaeli/catkin_ws/src/wheel_gazebo/urdf/wheel.stl"/>
			</geometry>
			<material name="wheel_material">
				<color rgba="0.615686 0.811765 0.929412 1.0"/>
			</material>
		</visual>
		<collision>
			<origin xyz="-1.41488e-17 -1.56125e-17 0.2032" rpy="0 -0.0149119 0" />
			<geometry>
				<mesh filename="file:///home/seanghaeli/catkin_ws/src/wheel_gazebo/urdf/wheel.stl"/>
			</geometry>
			<material name="wheel_material">
				<color rgba="0.615686 0.811765 0.929412 1.0"/>
			</material>
		</collision>
		<inertial>
			<origin xyz="-1.46354e-17 -2.08433e-17 0.2032" rpy="0 0 0"/>
			<mass value="0.534374" />
			<inertia ixx="0.00318283" ixy="0"  ixz="-2.68925e-21" iyy="0.00592742" iyz="0" izz="0.00318283" />
		</inertial>
	</link>
	
    <link name="base_link">
		<visual>
			<origin xyz="0 0 2.77556e-17" rpy="1.5708 -0 0" />
			<geometry>
				<mesh filename="file:///home/seanghaeli/catkin_ws/src/wheel_gazebo/urdf/base.stl"/>
			</geometry>
			<material name="base_material">
				<color rgba="0.647059 0.647059 0.647059 1.0"/>
			</material>
		</visual>
		<collision>
			<origin xyz="0 0 2.77556e-17" rpy="1.5708 -0 0" />
			<geometry>
				<mesh filename="file:///home/seanghaeli/catkin_ws/src/wheel_gazebo/urdf/base.stl"/>
			</geometry>
			<material name="base_material">
				<color rgba="0.647059 0.647059 0.647059 1.0"/>
			</material>
		</collision>
		<inertial>
			<origin xyz="1.16661e-17 0.16961 1.1502e-17" rpy="0 0 0"/>
			<mass value="11.195" />
			<inertia ixx="0.0514132" ixy="0"  ixz="0" iyy="0.0926616" iyz="0" izz="0.102411" />
		</inertial>
	</link>

    <!-- A simple fixed joint from our empty world link, to our base. -->
    <!-- The base origin is offset from the world origin. -->
    <joint name="base_joint" type="fixed">
        <origin xyz="1.5 1.0 0" rpy="0 0 0"/>
        <parent link="world"/>
        <child link="base_link"/>        
    </joint>

	<joint name="rev" type="continuous">
        <origin xyz="-7.60623e-18 -3.5982e-17 0.2032" rpy="1.5708 -0.868659 3.14159" />
		<parent link="base_link" />
		<child link="wheel" />
		<axis xyz="0 0 1"/>
		<limit effort="1" velocity="20" />
		<joint_properties friction="0.0"/>
	</joint>

	<gazebo reference="wheel">
		<material>Gazebo/Orange</material>
	</gazebo>
</robot>