<robot name="onshape">
    <link name="base_link">
        <visual>
            <origin xyz="-4.79462e-18 1.15648e-17 0.2794" rpy="0 -0 0" />
            <geometry>
                <mesh filename="file:///home/mackenzie/gym-gazebo-noetic/gym_gazebo/envs/ros_ws/src/wheel_gazebo/urdf/peanut/base.stl"/>
            </geometry>
            <material name="base_material">
                <color rgba="0.647059 0.647059 0.647059 1.0"/>
            </material>
        </visual>
        <collision>
            <origin xyz="-4.79462e-18 1.15648e-17 0.2794" rpy="0 -0 0" />
            <geometry>
                <mesh filename="file:///home/mackenzie/gym-gazebo-noetic/gym_gazebo/envs/ros_ws/src/wheel_gazebo/urdf/peanut/base.stl"/>
            </geometry>
            <material name="base_material">
                <color rgba="0.647059 0.647059 0.647059 1.0"/>
            </material>
        </collision>
        <inertial>
            <origin xyz="5.68017e-18 -3.78643e-18 0.0476673" rpy="0 0 0"/>
            <mass value="11.8457" />
            <inertia ixx="0.0918009" ixy="0" ixz="0" iyy="0.141715" iyz="0" izz="0.093834" />
        </inertial>
    </link>

    <link name="wheel">
        <visual>
            <origin xyz="6.16298e-33 0 0" rpy="1.5708 -5.01484e-33 -5.59652e-33" />
            <geometry>
                <mesh filename="file:///home/mackenzie/gym-gazebo-noetic/gym_gazebo/envs/ros_ws/src/wheel_gazebo/urdf/peanut/wheel.stl"/>
            </geometry>
            <material name="wheel_material">
                <color rgba="0.615686 0.811765 0.929412 1.0"/>
            </material>
        </visual>
        <collision>
            <origin xyz="6.16298e-33 0 0" rpy="1.5708 -5.01484e-33 -5.59652e-33" />
            <geometry>
                <mesh filename="file:///home/mackenzie/gym-gazebo-noetic/gym_gazebo/envs/ros_ws/src/wheel_gazebo/urdf/peanut/wheel.stl"/>
            </geometry>
            <material name="wheel_material">
                <color rgba="0.615686 0.811765 0.929412 1.0"/>
            </material>
        </collision>
        <inertial>
            <origin xyz="1.63479e-17 8.62316e-18 5.72264e-18" rpy="0 0 0"/>
            <mass value="0.742847" />
            <inertia ixx="0.00372784" ixy="3.98034e-35" ixz="8.866e-35" iyy="0.01084" iyz="4.99713e-36" izz="0.0139517" />
        </inertial>
    </link>

    <joint name="rev" type="continuous">
        <origin xyz="-5.55112e-17 -1.61908e-17 0.2794" rpy="1.5708 6.12323e-17 -3.14159" />
        <parent link="base_link" />
        <child link="wheel" />
        <axis xyz="0 0 1"/>
        <limit effort="1" velocity="20" />
        <joint_properties friction="0.0"/>
    </joint>


<link name="world"></link>

    <joint name="base_joint" type="fixed">
        <origin xyz="0 0 0" rpy="0 0 0" />
        <parent link="world" />
        <child link="base_link" />
    </joint>

    <joint name="camera_joint" type="fixed">
        <axis xyz="1 0 0" />
        <origin xyz="0 1 .3" rpy="0 0 -1.57079632679"/>
        <parent link="world"/>
        <child link="camera_link"/>
    </joint>
    <link name="camera_link">
        <collision>
            <origin xyz="0 0 0" rpy="0 0 0"/>
            <geometry>
                <box size="0.05 0.05 0.05"/>
            </geometry>
        </collision>

        <visual>
            <origin xyz="0 0 0" rpy="0 0 0"/>
            <geometry>
                <box size="0.05 0.05 0.05"/>
            </geometry>
            <material name="red"/>
        </visual>

        <inertial>
            <mass value="1e-5" />
            <origin xyz="0 0 0" rpy="0 0 0"/>
            <inertia ixx="1e-6" ixy="0" ixz="0" iyy="1e-6" iyz="0" izz="1e-6" />
        </inertial>
    </link>
    <gazebo reference="camera_link">
        <sensor type="camera" name="camera1">
            <update_rate>30.0</update_rate>
            <camera name="head">
                <horizontal_fov>1.3962634</horizontal_fov>
                <image>
                    <width>800</width>
                    <height>800</height>
                    <format>R8G8B8</format>
                </image>
                <clip>
                    <near>0.02</near>
                    <far>300</far>
                </clip>
                <noise>
                    <type>gaussian</type>
                    <!-- Noise is sampled independently per pixel on each frame.
               That pixel's noise value is added to each of its color
               channels, which at that point lie in the range [0,1]. -->
                    <mean>0.0</mean>
                    <stddev>0.007</stddev>
                </noise>
            </camera>
            <plugin name="camera_controller" filename="libgazebo_ros_camera.so">
                <alwaysOn>true</alwaysOn>
                <updateRate>0.0</updateRate>
                <cameraName>wheel/camera1</cameraName>
                <imageTopicName>image_raw</imageTopicName>
                <cameraInfoTopicName>camera_info</cameraInfoTopicName>
                <frameName>camera_link</frameName>
                <hackBaseline>0.07</hackBaseline>
                <distortionK1>0.0</distortionK1>
                <distortionK2>0.0</distortionK2>
                <distortionK3>0.0</distortionK3>
                <distortionT1>0.0</distortionT1>
                <distortionT2>0.0</distortionT2>
            </plugin>
        </sensor>
    </gazebo>
    <gazebo reference="wheel">
        <material>Gazebo/Orange</material>
    </gazebo>
    <gazebo>
        <plugin name="gazebo_ros_control" filename="libgazebo_ros_control.so">
            <robotNamespace>/wheel</robotNamespace>

        </plugin>
        <gazebo>
            <plugin name="gazebo_ros_joint_state_publisher" filename="libgazebo_ros_joint_state_publisher.so">
                <updateRate>20</updateRate>
                <joint_name>rev</joint_name>
            </plugin>
        </gazebo>
    </gazebo>
    <transmission name="tran1">
        <type>transmission_interface/SimpleTransmission</type>
        <joint name="rev">
            <hardwareInterface>hardware_interface/EffortJointInterface</hardwareInterface>
        </joint>
        <actuator name="motor1">
            <hardwareInterface>hardware_interface/EffortJointInterface</hardwareInterface>
            <mechanicalReduction>1</mechanicalReduction>
        </actuator>
    </transmission>
</robot>
