<robot name="Wheel">
	<link name="part_2">
		<visual>
			<origin xyz="-2.77556e-17 1.9082e-17 0.2032" rpy="0 -0 0" />
			<geometry>
				<mesh filename="part_2.stl"/>
			</geometry>
			<material name="part_2_material">
				<color rgba="0.647059 0.647059 0.647059 1.0"/>
			</material>
		</visual>
		<collision>
			<origin xyz="-2.77556e-17 1.9082e-17 0.2032" rpy="0 -0 0" />
			<geometry>
				<mesh filename="part_2.stl"/>
			</geometry>
			<material name="part_2_material">
				<color rgba="0.647059 0.647059 0.647059 1.0"/>
			</material>
		</collision>
		<inertial>
			<origin xyz="-4.34574e-17 8.76783e-18 0.0335895" rpy="0 0 0"/>
			<mass value="11.195" />
			<inertia ixx="0.0514132" ixy="0"  ixz="0" iyy="0.102411" iyz="0" izz="0.0926616" />
		</inertial>
	</link>
	<link name="wheel">
		<visual>
			<origin xyz="-2.77556e-17 0 1.38778e-17" rpy="1.5708 -0 -5.6974e-18" />
			<geometry>
				<mesh filename="wheel.stl"/>
			</geometry>
			<material name="wheel_material">
				<color rgba="0.615686 0.811765 0.929412 1.0"/>
			</material>
		</visual>
		<collision>
			<origin xyz="-2.77556e-17 0 1.38778e-17" rpy="1.5708 -0 -5.6974e-18" />
			<geometry>
				<mesh filename="wheel.stl"/>
			</geometry>
			<material name="wheel_material">
				<color rgba="0.615686 0.811765 0.929412 1.0"/>
			</material>
		</collision>
		<inertial>
			<origin xyz="-2.78024e-17 -1.24009e-17 1.20479e-17" rpy="0 0 0"/>
			<mass value="4.04156" />
			<inertia ixx="0.0245421" ixy="-3.3874e-18"  ixz="0" iyy="0.0245421" iyz="0" izz="0.0473459" />
		</inertial>
	</link>
	<joint name="wheel" type="revolute">
		<origin xyz="-2.81661e-17 -8.67362e-18 0.2032" rpy="-1.5708 0.880047 0" />
		<parent link="part_2" />
		<child link="wheel" />
		<axis xyz="0 0 1"/>
		<limit effort="1" velocity="20" />
		<joint_properties friction="0.0"/>
	</joint>
</robot>
